<?xml version="1.0" ?>
<sdf version="1.6">
  <model name="x3_lidar">
    <pose>0 0 0.1 0 0 0</pose>

    <link name="base_link">
      <pose>0 0 0 0 0 0</pose>
      <gravity>false</gravity>
      <inertial>
        <mass>1.5</mass>
        <inertia><ixx>0.0347563</ixx><ixy>0</ixy><ixz>0</ixz><iyy>0.07</iyy><iyz>0</iyz><izz>0.0977</izz></inertia>
      </inertial>
      <collision name="base_collision">
        <geometry><box><size>0.47 0.47 0.11</size></box></geometry>
      </collision>
      <visual name="base_visual">
        <geometry><mesh><scale>1 1 1</scale><uri>model://x3_lidar/meshes/x3.dae</uri></mesh></geometry>
      </visual>

      <sensor name="lidar" type="ray">
        <pose>0 0 0.1 0 0 0</pose>
        <always_on>true</always_on>
        <update_rate>10</update_rate>
        <visualize>false</visualize>
        <ray>
          <scan>
            <horizontal><samples>360</samples><resolution>1</resolution><min_angle>-3.14159</min_angle><max_angle>3.14159</max_angle></horizontal>
            <vertical><samples>16</samples><resolution>1</resolution><min_angle>-0.261799</min_angle><max_angle>0.261799</max_angle></vertical>
          </scan>
          <range><min>0.1</min><max>15.0</max><resolution>0.01</resolution></range>
          <noise><type>gaussian</type><mean>0.0</mean><stddev>0.01</stddev></noise>
        </ray>
        <plugin name="lidar_plugin" filename="libgazebo_ros_ray_sensor.so">
          <ros><remapping>~/out:=/lidar/points</remapping></ros>
          <output_type>sensor_msgs/PointCloud2</output_type>
          <frame_name>base_link</frame_name>
        </plugin>
      </sensor>

      <sensor name="imu_sensor" type="imu">
        <pose>0 0 0 0 0 0</pose>
        <always_on>true</always_on>
        <update_rate>100</update_rate>
        <plugin name="imu_plugin" filename="libgazebo_ros_imu_sensor.so">
          <ros><remapping>~/out:=/imu/data</remapping></ros>
          <initial_orientation_as_reference>false</initial_orientation_as_reference>
          <frame_name>base_link</frame_name>
        </plugin>
      </sensor>
    </link>

    <link name="rotor_0">
      <pose>0.13 -0.22 0.023 0 0 0</pose><gravity>false</gravity>
      <inertial><mass>0.005</mass><inertia><ixx>9.75e-07</ixx><ixy>0</ixy><ixz>0</ixz><iyy>4.17041e-05</iyy><iyz>0</iyz><izz>4.26041e-05</izz></inertia></inertial>
      <collision name="c"><geometry><cylinder><length>0.005</length><radius>0.1</radius></cylinder></geometry></collision>
      <visual name="v"><geometry><mesh><scale>0.1 0.1 0.1</scale><uri>model://x3_lidar/meshes/propeller_ccw.dae</uri></mesh></geometry>
      <material><script><name>Gazebo/Blue</name><uri>file://media/materials/scripts/gazebo.material</uri></script></material></visual>
    </link>
    <joint name="rotor_0_joint" type="revolute"><child>rotor_0</child><parent>base_link</parent><axis><xyz>0 0 1</xyz><limit><lower>-1e16</lower><upper>1e16</upper></limit></axis></joint>

    <link name="rotor_1">
      <pose>-0.13 0.2 0.023 0 0 0</pose><gravity>false</gravity>
      <inertial><mass>0.005</mass><inertia><ixx>9.75e-07</ixx><ixy>0</ixy><ixz>0</ixz><iyy>4.17041e-05</iyy><iyz>0</iyz><izz>4.26041e-05</izz></inertia></inertial>
      <collision name="c"><geometry><cylinder><length>0.005</length><radius>0.1</radius></cylinder></geometry></collision>
      <visual name="v"><geometry><mesh><scale>0.1 0.1 0.1</scale><uri>model://x3_lidar/meshes/propeller_ccw.dae</uri></mesh></geometry>
      <material><script><name>Gazebo/Red</name><uri>file://media/materials/scripts/gazebo.material</uri></script></material></visual>
    </link>
    <joint name="rotor_1_joint" type="revolute"><child>rotor_1</child><parent>base_link</parent><axis><xyz>0 0 1</xyz><limit><lower>-1e16</lower><upper>1e16</upper></limit></axis></joint>

    <link name="rotor_2">
      <pose>0.13 0.22 0.023 0 0 0</pose><gravity>false</gravity>
      <inertial><mass>0.005</mass><inertia><ixx>9.75e-07</ixx><ixy>0</ixy><ixz>0</ixz><iyy>4.17041e-05</iyy><iyz>0</iyz><izz>4.26041e-05</izz></inertia></inertial>
      <collision name="c"><geometry><cylinder><length>0.005</length><radius>0.1</radius></cylinder></geometry></collision>
      <visual name="v"><geometry><mesh><scale>0.1 0.1 0.1</scale><uri>model://x3_lidar/meshes/propeller_cw.dae</uri></mesh></geometry>
      <material><script><name>Gazebo/Blue</name><uri>file://media/materials/scripts/gazebo.material</uri></script></material></visual>
    </link>
    <joint name="rotor_2_joint" type="revolute"><child>rotor_2</child><parent>base_link</parent><axis><xyz>0 0 1</xyz><limit><lower>-1e16</lower><upper>1e16</upper></limit></axis></joint>

    <link name="rotor_3">
      <pose>-0.13 -0.2 0.023 0 0 0</pose><gravity>false</gravity>
      <inertial><mass>0.005</mass><inertia><ixx>9.75e-07</ixx><ixy>0</ixy><ixz>0</ixz><iyy>4.17041e-05</iyy><iyz>0</iyz><izz>4.26041e-05</izz></inertia></inertial>
      <collision name="c"><geometry><cylinder><length>0.005</length><radius>0.1</radius></cylinder></geometry></collision>
      <visual name="v"><geometry><mesh><scale>0.1 0.1 0.1</scale><uri>model://x3_lidar/meshes/propeller_cw.dae</uri></mesh></geometry>
      <material><script><name>Gazebo/Red</name><uri>file://media/materials/scripts/gazebo.material</uri></script></material></visual>
    </link>
    <joint name="rotor_3_joint" type="revolute"><child>rotor_3</child><parent>base_link</parent><axis><xyz>0 0 1</xyz><limit><lower>-1e16</lower><upper>1e16</upper></limit></axis></joint>

    <plugin name="drone_move" filename="libgazebo_ros_planar_move.so">
    <ros>
      <remapping>cmd_vel:=/cmd_vel</remapping>
      <remapping>odom:=/odom_planar</remapping>
    </ros>
    <update_rate>50</update_rate>
    <publish_odom>true</publish_odom>
    <publish_odom_tf>false</publish_odom_tf>
    <odometry_frame>odom</odometry_frame>
    <robot_base_frame>base_link</robot_base_frame>
  </plugin>
  <link name="camera_link">
    <pose>0.15 0 0.05 0 0 0</pose>
    <gravity>false</gravity>
    <inertial><mass>0.01</mass><inertia><ixx>1e-5</ixx><ixy>0</ixy><ixz>0</ixz><iyy>1e-5</iyy><iyz>0</iyz><izz>1e-5</izz></inertia></inertial>
    <visual name="cam_vis">
      <pose>0 0 0 0 0 0</pose>
      <geometry><box><size>0.03 0.03 0.03</size></box></geometry>
      <material><script><name>Gazebo/Black</name><uri>file://media/materials/scripts/gazebo.material</uri></script></material>
    </visual>
    <sensor name="front_camera" type="camera">
      <pose>0 0 0 0 0 0</pose>
      <always_on>true</always_on>
      <update_rate>10</update_rate>
      <visualize>false</visualize>
      <camera>
        <horizontal_fov>1.047</horizontal_fov>
        <image><width>640</width><height>480</height><format>R8G8B8</format></image>
        <clip><near>0.05</near><far>50.0</far></clip>
      </camera>
      <plugin name="camera_plugin" filename="libgazebo_ros_camera.so">
        <ros><remapping>~/image_raw:=/camera/image_raw</remapping><remapping>~/camera_info:=/camera/camera_info</remapping></ros>
        <camera_name>front_camera</camera_name>
        <frame_name>camera_link</frame_name>
      </plugin>
    </sensor>
  </link>
  <joint name="camera_joint" type="fixed">
    <parent>base_link</parent>
    <child>camera_link</child>
  </joint>
</model>
</sdf>
<!-- This line is wrong, use sed instead -->
